Workbook

Sheet Summary
A1: Posture Detection Accuracy - Pilot Round
A2: Pilot data from the pre-Phase-29 analyser (old thresholds). All figures are formulas over Raw Data.
A4: Target accuracy | B4: 0.75 | C4: Objective 2 target (revised from 90% in the proposal)
A5: z (95% CI) | B5: 1.96 | C5: Wilson score interval
A7: Exercise | B7: Testers | C7: Reps | D7: TP | E7: TN | F7: FP | G7: FN | H7: Accuracy | I7: 95% CI low | J7: 95% CI high | K7: Precision | L7: Recall | M7: Specificity | N7: F1 | O7: Meets target?
A8: Push-up | B8: 2 | C8: =SUM(D8:G8) -> 20 | D8: =COUNTIFS('Raw Data'!$J$2:$J$1000,"TP",'Raw Data'!$C$2:$C$1000,$A8) -> 6 | E8: =COUNTIFS('Raw Data'!$J$2:$J$1000,"TN",'Raw Data'!$C$2:$C$1000,$A8) -> 9 | F8: =COUNTIFS('Raw Data'!$J$2:$J$1000,"FP",'Raw Data'!$C$2:$C$1000,$A8) -> 1 | G8: =COUNTIFS('Raw Data'!$J$2:$J$1000,"FN",'Raw Data'!$C$2:$C$1000,$A8) -> 4 | H8: =IF(C8=0,"",(D8+E8)/C8) -> 0.75 | I8: =IF(C8=0,"",(H8+$B$5^2/(2*C8)-$B$5*SQRT(H8*(1-H8)/C8+$B$5^2/(4*C8^2)))/(1+$B$5^2/C8)) -> 0.53129499 | J8: =IF(C8=0,"",(H8+$B$5^2/(2*C8)+$B$5*SQRT(H8*(1-H8)/C8+$B$5^2/(4*C8^2)))/(1+$B$5^2/C8)) -> 0.88813995 | K8: =IF(D8+F8=0,"",D8/(D8+F8)) -> 0.85714286 | L8: =IF(D8+G8=0,"",D8/(D8+G8)) -> 0.6 | M8: =IF(E8+F8=0,"",E8/(E8+F8)) -> 0.9 | N8: =IF(OR(K8="",L8=""),"",IF(K8+L8=0,0,2*K8*L8/(K8+L8))) -> 0.70588235 | O8: =IF(H8="","",IF(H8>=$B$4,"Yes","No")) -> Yes
A9: Squat | B9: 3 | C9: =SUM(D9:G9) -> 27 | D9: =COUNTIFS('Raw Data'!$J$2:$J$1000,"TP",'Raw Data'!$C$2:$C$1000,$A9) -> 12 | E9: =COUNTIFS('Raw Data'!$J$2:$J$1000,"TN",'Raw Data'!$C$2:$C$1000,$A9) -> 11 | F9: =COUNTIFS('Raw Data'!$J$2:$J$1000,"FP",'Raw Data'!$C$2:$C$1000,$A9) -> 3 | G9: =COUNTIFS('Raw Data'!$J$2:$J$1000,"FN",'Raw Data'!$C$2:$C$1000,$A9) -> 1 | H9: =IF(C9=0,"",(D9+E9)/C9) -> 0.85185185 | I9: =IF(C9=0,"",(H9+$B$5^2/(2*C9)-$B$5*SQRT(H9*(1-H9)/C9+$B$5^2/(4*C9^2)))/(1+$B$5^2/C9)) -> 0.67520937 | J9: =IF(C9=0,"",(H9+$B$5^2/(2*C9)+$B$5*SQRT(H9*(1-H9)/C9+$B$5^2/(4*C9^2)))/(1+$B$5^2/C9)) -> 0.94084168 | K9: =IF(D9+F9=0,"",D9/(D9+F9)) -> 0.8 | L9: =IF(D9+G9=0,"",D9/(D9+G9)) -> 0.92307692 | M9: =IF(E9+F9=0,"",E9/(E9+F9)) -> 0.78571429 | N9: =IF(OR(K9="",L9=""),"",IF(K9+L9=0,0,2*K9*L9/(K9+L9))) -> 0.85714286 | O9: =IF(H9="","",IF(H9>=$B$4,"Yes","No")) -> Yes
A10: OVERALL | B10: =MAX(B8:B9) -> 3 | C10: =SUM(D10:G10) -> 47 | D10: =COUNTIFS('Raw Data'!$J$2:$J$1000,"TP") -> 18 | E10: =COUNTIFS('Raw Data'!$J$2:$J$1000,"TN") -> 20 | F10: =COUNTIFS('Raw Data'!$J$2:$J$1000,"FP") -> 4 | G10: =COUNTIFS('Raw Data'!$J$2:$J$1000,"FN") -> 5 | H10: =IF(C10=0,"",(D10+E10)/C10) -> 0.80851064 | I10: =IF(C10=0,"",(H10+$B$5^2/(2*C10)-$B$5*SQRT(H10*(1-H10)/C10+$B$5^2/(4*C10^2)))/(1+$B$5^2/C10)) -> 0.6745572 | J10: =IF(C10=0,"",(H10+$B$5^2/(2*C10)+$B$5*SQRT(H10*(1-H10)/C10+$B$5^2/(4*C10^2)))/(1+$B$5^2/C10)) -> 0.89584184 | K10: =IF(D10+F10=0,"",D10/(D10+F10)) -> 0.81818182 | L10: =IF(D10+G10=0,"",D10/(D10+G10)) -> 0.7826087 | M10: =IF(E10+F10=0,"",E10/(E10+F10)) -> 0.83333333 | N10: =IF(OR(K10="",L10=""),"",IF(K10+L10=0,0,2*K10*L10/(K10+L10))) -> 0.8 | O10: =IF(H10="","",IF(H10>=$B$4,"Yes","No")) -> Yes
A11: Positive class = INCORRECT form. Recall = share of bad reps the app caught; Specificity = share of good reps it correctly passed. Testers column is typed in (blue).
A13: Confusion matrix - Push-up
B14: Predicted Correct | C14: Predicted Incorrect | D14: Total
A15: Actual Correct | B15: =E8 -> 9 | C15: =F8 -> 1 | D15: =B15+C15 -> 10
A16: Actual Incorrect | B16: =G8 -> 4 | C16: =D8 -> 6 | D16: =B16+C16 -> 10
A19: Confusion matrix - Squat
B20: Predicted Correct | C20: Predicted Incorrect | D20: Total
A21: Actual Correct | B21: =E9 -> 11 | C21: =F9 -> 3 | D21: =B21+C21 -> 14
A22: Actual Incorrect | B22: =G9 -> 1 | C22: =D9 -> 12 | D22: =B22+C22 -> 13
A25: Accuracy by tester
A26: Exercise | B26: Tester | C26: Reps | D26: Matches | E26: Accuracy
A27: Push-up | B27: T01 | C27: =COUNTIFS('Raw Data'!$C$2:$C$1000,A27,'Raw Data'!$B$2:$B$1000,B27,'Raw Data'!$K$2:$K$1000,"<>") -> 10 | D27: =SUMIFS('Raw Data'!$K$2:$K$1000,'Raw Data'!$C$2:$C$1000,A27,'Raw Data'!$B$2:$B$1000,B27) -> 9 | E27: =IF(C27=0,"no data",D27/C27) -> 0.9
A28: Push-up | B28: T02 | C28: =COUNTIFS('Raw Data'!$C$2:$C$1000,A28,'Raw Data'!$B$2:$B$1000,B28,'Raw Data'!$K$2:$K$1000,"<>") -> 0 | D28: =SUMIFS('Raw Data'!$K$2:$K$1000,'Raw Data'!$C$2:$C$1000,A28,'Raw Data'!$B$2:$B$1000,B28) -> 0 | E28: =IF(C28=0,"no data",D28/C28) -> no data
A29: Push-up | B29: T03 | C29: =COUNTIFS('Raw Data'!$C$2:$C$1000,A29,'Raw Data'!$B$2:$B$1000,B29,'Raw Data'!$K$2:$K$1000,"<>") -> 10 | D29: =SUMIFS('Raw Data'!$K$2:$K$1000,'Raw Data'!$C$2:$C$1000,A29,'Raw Data'!$B$2:$B$1000,B29) -> 6 | E29: =IF(C29=0,"no data",D29/C29) -> 0.6
A30: Squat | B30: T01 | C30: =COUNTIFS('Raw Data'!$C$2:$C$1000,A30,'Raw Data'!$B$2:$B$1000,B30,'Raw Data'!$K$2:$K$1000,"<>") -> 8 | D30: =SUMIFS('Raw Data'!$K$2:$K$1000,'Raw Data'!$C$2:$C$1000,A30,'Raw Data'!$B$2:$B$1000,B30) -> 7 | E30: =IF(C30=0,"no data",D30/C30) -> 0.875
A31: Squat | B31: T02 | C31: =COUNTIFS('Raw Data'!$C$2:$C$1000,A31,'Raw Data'!$B$2:$B$1000,B31,'Raw Data'!$K$2:$K$1000,"<>") -> 9 | D31: =SUMIFS('Raw Data'!$K$2:$K$1000,'Raw Data'!$C$2:$C$1000,A31,'Raw Data'!$B$2:$B$1000,B31) -> 9 | E31: =IF(C31=0,"no data",D31/C31) -> 1
A32: Squat | B32: T03 | C32: =COUNTIFS('Raw Data'!$C$2:$C$1000,A32,'Raw Data'!$B$2:$B$1000,B32,'Raw Data'!$K$2:$K$1000,"<>") -> 10 | D32: =SUMIFS('Raw Data'!$K$2:$K$1000,'Raw Data'!$C$2:$C$1000,A32,'Raw Data'!$B$2:$B$1000,B32) -> 7 | E32: =IF(C32=0,"no data",D32/C32) -> 0.7

Sheet Raw Data
A1: Round | B1: Tester | C1: Exercise | D1: Rep | E1: Primary angle (°) | F1: Body line (°) | G1: App verdict | H1: Ground truth | I1: Fault | J1: Outcome | K1: Match | L1: Notes
A2: Pilot (pre-Phase 29) | B2: T01 | C2: Push-up | D2: 1 | E2: 67.4 | F2: 178 | G2: Correct | H2: Correct | J2: =IF(H2="","",IF(H2="Incorrect",IF(G2="Incorrect","TP","FN"),IF(G2="Incorrect","FP","TN"))) -> TN | K2: =IF(H2="","",IF(G2=H2,1,0)) -> 1
A3: Pilot (pre-Phase 29) | B3: T01 | C3: Push-up | D3: 2 | E3: 56 | F3: 166.6 | G3: Correct | H3: Correct | J3: =IF(H3="","",IF(H3="Incorrect",IF(G3="Incorrect","TP","FN"),IF(G3="Incorrect","FP","TN"))) -> TN | K3: =IF(H3="","",IF(G3=H3,1,0)) -> 1
A4: Pilot (pre-Phase 29) | B4: T01 | C4: Push-up | D4: 3 | E4: 46 | F4: 162.6 | G4: Correct | H4: Correct | J4: =IF(H4="","",IF(H4="Incorrect",IF(G4="Incorrect","TP","FN"),IF(G4="Incorrect","FP","TN"))) -> TN | K4: =IF(H4="","",IF(G4=H4,1,0)) -> 1
A5: Pilot (pre-Phase 29) | B5: T01 | C5: Push-up | D5: 4 | E5: 62.8 | F5: 165.1 | G5: Correct | H5: Correct | J5: =IF(H5="","",IF(H5="Incorrect",IF(G5="Incorrect","TP","FN"),IF(G5="Incorrect","FP","TN"))) -> TN | K5: =IF(H5="","",IF(G5=H5,1,0)) -> 1
A6: Pilot (pre-Phase 29) | B6: T01 | C6: Push-up | D6: 5 | E6: 68.3 | F6: 163.9 | G6: Correct | H6: Correct | J6: =IF(H6="","",IF(H6="Incorrect",IF(G6="Incorrect","TP","FN"),IF(G6="Incorrect","FP","TN"))) -> TN | K6: =IF(H6="","",IF(G6=H6,1,0)) -> 1
A7: Pilot (pre-Phase 29) | B7: T01 | C7: Push-up | D7: 6 | E7: 102.1 | F7: 147.4 | G7: Incorrect | H7: Incorrect | I7: not recorded | J7: =IF(H7="","",IF(H7="Incorrect",IF(G7="Incorrect","TP","FN"),IF(G7="Incorrect","FP","TN"))) -> TP | K7: =IF(H7="","",IF(G7=H7,1,0)) -> 1
A8: Pilot (pre-Phase 29) | B8: T01 | C8: Push-up | D8: 7 | E8: 37.2 | F8: 131.1 | G8: Incorrect | H8: Incorrect | I8: not recorded | J8: =IF(H8="","",IF(H8="Incorrect",IF(G8="Incorrect","TP","FN"),IF(G8="Incorrect","FP","TN"))) -> TP | K8: =IF(H8="","",IF(G8=H8,1,0)) -> 1
A9: Pilot (pre-Phase 29) | B9: T01 | C9: Push-up | D9: 8 | E9: 62.1 | F9: 164.7 | G9: Correct | H9: Incorrect | I9: not recorded | J9: =IF(H9="","",IF(H9="Incorrect",IF(G9="Incorrect","TP","FN"),IF(G9="Incorrect","FP","TN"))) -> FN | K9: =IF(H9="","",IF(G9=H9,1,0)) -> 0
A10: Pilot (pre-Phase 29) | B10: T01 | C10: Push-up | D10: 9 | E10: 97.3 | F10: 136.5 | G10: Incorrect | H10: Incorrect | I10: not recorded | J10: =IF(H10="","",IF(H10="Incorrect",IF(G10="Incorrect","TP","FN"),IF(G10="Incorrect","FP","TN"))) -> TP | K10: =IF(H10="","",IF(G10=H10,1,0)) -> 1
A11: Pilot (pre-Phase 29) | B11: T01 | C11: Push-up | D11: 10 | E11: 85.6 | F11: 147.5 | G11: Incorrect | H11: Incorrect | I11: not recorded | J11: =IF(H11="","",IF(H11="Incorrect",IF(G11="Incorrect","TP","FN"),IF(G11="Incorrect","FP","TN"))) -> TP | K11: =IF(H11="","",IF(G11=H11,1,0)) -> 1
A12: Pilot (pre-Phase 29) | B12: T03 | C12: Push-up | D12: 1 | E12: 82.2 | F12: 168.2 | G12: Correct | H12: Correct | J12: =IF(H12="","",IF(H12="Incorrect",IF(G12="Incorrect","TP","FN"),IF(G12="Incorrect","FP","TN"))) -> TN | K12: =IF(H12="","",IF(G12=H12,1,0)) -> 1 | L12: Ground truth ASSUMED (first 5 correct, last 5 wrong) - confirm
A13: Pilot (pre-Phase 29) | B13: T03 | C13: Push-up | D13: 2 | E13: 83 | F13: 158.9 | G13: Incorrect | H13: Correct | J13: =IF(H13="","",IF(H13="Incorrect",IF(G13="Incorrect","TP","FN"),IF(G13="Incorrect","FP","TN"))) -> FP | K13: =IF(H13="","",IF(G13=H13,1,0)) -> 0 | L13: Ground truth ASSUMED (first 5 correct, last 5 wrong) - confirm
A14: Pilot (pre-Phase 29) | B14: T03 | C14: Push-up | D14: 3 | E14: 96.1 | F14: 165.1 | G14: Correct | H14: Correct | J14: =IF(H14="","",IF(H14="Incorrect",IF(G14="Incorrect","TP","FN"),IF(G14="Incorrect","FP","TN"))) -> TN | K14: =IF(H14="","",IF(G14=H14,1,0)) -> 1 | L14: Ground truth ASSUMED (first 5 correct, last 5 wrong) - confirm
A15: Pilot (pre-Phase 29) | B15: T03 | C15: Push-up | D15: 4 | E15: 90.7 | F15: 162.9 | G15: Correct | H15: Correct | J15: =IF(H15="","",IF(H15="Incorrect",IF(G15="Incorrect","TP","FN"),IF(G15="Incorrect","FP","TN"))) -> TN | K15: =IF(H15="","",IF(G15=H15,1,0)) -> 1 | L15: Ground truth ASSUMED (first 5 correct, last 5 wrong) - confirm
A16: Pilot (pre-Phase 29) | B16: T03 | C16: Push-up | D16: 5 | E16: 87.6 | F16: 160.9 | G16: Correct | H16: Correct | J16: =IF(H16="","",IF(H16="Incorrect",IF(G16="Incorrect","TP","FN"),IF(G16="Incorrect","FP","TN"))) -> TN | K16: =IF(H16="","",IF(G16=H16,1,0)) -> 1 | L16: Ground truth ASSUMED (first 5 correct, last 5 wrong) - confirm
A17: Pilot (pre-Phase 29) | B17: T03 | C17: Push-up | D17: 6 | E17: 91.2 | F17: 155.8 | G17: Incorrect | H17: Incorrect | I17: not recorded | J17: =IF(H17="","",IF(H17="Incorrect",IF(G17="Incorrect","TP","FN"),IF(G17="Incorrect","FP","TN"))) -> TP | K17: =IF(H17="","",IF(G17=H17,1,0)) -> 1 | L17: Ground truth ASSUMED (first 5 correct, last 5 wrong) - confirm
A18: Pilot (pre-Phase 29) | B18: T03 | C18: Push-up | D18: 7 | E18: 87.6 | F18: 158.2 | G18: Incorrect | H18: Incorrect | I18: not recorded | J18: =IF(H18="","",IF(H18="Incorrect",IF(G18="Incorrect","TP","FN"),IF(G18="Incorrect","FP","TN"))) -> TP | K18: =IF(H18="","",IF(G18=H18,1,0)) -> 1 | L18: Ground truth ASSUMED (first 5 correct, last 5 wrong) - confirm
A19: Pilot (pre-Phase 29) | B19: T03 | C19: Push-up | D19: 8 | E19: 94.6 | F19: 170.7 | G19: Correct | H19: Incorrect | I19: not recorded | J19: =IF(H19="","",IF(H19="Incorrect",IF(G19="Incorrect","TP","FN"),IF(G19="Incorrect","FP","TN"))) -> FN | K19: =IF(H19="","",IF(G19=H19,1,0)) -> 0 | L19: Ground truth ASSUMED (first 5 correct, last 5 wrong) - confirm
A20: Pilot (pre-Phase 29) | B20: T03 | C20: Push-up | D20: 9 | E20: 85.7 | F20: 169.4 | G20: Correct | H20: Incorrect | I20: not recorded | J20: =IF(H20="","",IF(H20="Incorrect",IF(G20="Incorrect","TP","FN"),IF(G20="Incorrect","FP","TN"))) -> FN | K20: =IF(H20="","",IF(G20=H20,1,0)) -> 0 | L20: Ground truth ASSUMED (first 5 correct, last 5 wrong) - confirm
A21: Pilot (pre-Phase 29) | B21: T03 | C21: Push-up | D21: 10 | E21: 83.6 | F21: 167.9 | G21: Correct | H21: Incorrect | I21: not recorded | J21: =IF(H21="","",IF(H21="Incorrect",IF(G21="Incorrect","TP","FN"),IF(G21="Incorrect","FP","TN"))) -> FN | K21: =IF(H21="","",IF(G21=H21,1,0)) -> 0 | L21: Ground truth ASSUMED (first 5 correct, last 5 wrong) - confirm
A22: Pilot (pre-Phase 29) | B22: T01 | C22: Squat | D22: 3 | E22: 33.2 | G22: Incorrect | H22: Correct | J22: =IF(H22="","",IF(H22="Incorrect",IF(G22="Incorrect","TP","FN"),IF(G22="Incorrect","FP","TN"))) -> FP | K22: =IF(H22="","",IF(G22=H22,1,0)) -> 0 | L22: Labelled correct but knee 33.2° is very deep - check
A23: Pilot (pre-Phase 29) | B23: T01 | C23: Squat | D23: 4 | E23: 85.4 | G23: Correct | H23: Correct | J23: =IF(H23="","",IF(H23="Incorrect",IF(G23="Incorrect","TP","FN"),IF(G23="Incorrect","FP","TN"))) -> TN | K23: =IF(H23="","",IF(G23=H23,1,0)) -> 1
A24: Pilot (pre-Phase 29) | B24: T01 | C24: Squat | D24: 5 | E24: 82.8 | G24: Correct | H24: Correct | J24: =IF(H24="","",IF(H24="Incorrect",IF(G24="Incorrect","TP","FN"),IF(G24="Incorrect","FP","TN"))) -> TN | K24: =IF(H24="","",IF(G24=H24,1,0)) -> 1
A25: Pilot (pre-Phase 29) | B25: T01 | C25: Squat | D25: 6 | E25: 88.6 | G25: Correct | H25: Correct | J25: =IF(H25="","",IF(H25="Incorrect",IF(G25="Incorrect","TP","FN"),IF(G25="Incorrect","FP","TN"))) -> TN | K25: =IF(H25="","",IF(G25=H25,1,0)) -> 1
A26: Pilot (pre-Phase 29) | B26: T01 | C26: Squat | D26: 7 | E26: 44.3 | G26: Incorrect | H26: Incorrect | I26: too_deep | J26: =IF(H26="","",IF(H26="Incorrect",IF(G26="Incorrect","TP","FN"),IF(G26="Incorrect","FP","TN"))) -> TP | K26: =IF(H26="","",IF(G26=H26,1,0)) -> 1
A27: Pilot (pre-Phase 29) | B27: T01 | C27: Squat | D27: 8 | E27: 44.6 | G27: Incorrect | H27: Incorrect | I27: too_deep | J27: =IF(H27="","",IF(H27="Incorrect",IF(G27="Incorrect","TP","FN"),IF(G27="Incorrect","FP","TN"))) -> TP | K27: =IF(H27="","",IF(G27=H27,1,0)) -> 1
A28: Pilot (pre-Phase 29) | B28: T01 | C28: Squat | D28: 9 | E28: 50.5 | G28: Incorrect | H28: Incorrect | I28: too_deep | J28: =IF(H28="","",IF(H28="Incorrect",IF(G28="Incorrect","TP","FN"),IF(G28="Incorrect","FP","TN"))) -> TP | K28: =IF(H28="","",IF(G28=H28,1,0)) -> 1 | L28: Log line was truncated ("LIDATION|...") - values intact
A29: Pilot (pre-Phase 29) | B29: T01 | C29: Squat | D29: 10 | E29: 52.7 | G29: Incorrect | H29: Incorrect | I29: too_deep | J29: =IF(H29="","",IF(H29="Incorrect",IF(G29="Incorrect","TP","FN"),IF(G29="Incorrect","FP","TN"))) -> TP | K29: =IF(H29="","",IF(G29=H29,1,0)) -> 1
A30: Pilot (pre-Phase 29) | B30: T02 | C30: Squat | D30: 2 | E30: 86.9 | G30: Correct | H30: Correct | J30: =IF(H30="","",IF(H30="Incorrect",IF(G30="Incorrect","TP","FN"),IF(G30="Incorrect","FP","TN"))) -> TN | K30: =IF(H30="","",IF(G30=H30,1,0)) -> 1
A31: Pilot (pre-Phase 29) | B31: T02 | C31: Squat | D31: 3 | E31: 85.6 | G31: Correct | H31: Correct | J31: =IF(H31="","",IF(H31="Incorrect",IF(G31="Incorrect","TP","FN"),IF(G31="Incorrect","FP","TN"))) -> TN | K31: =IF(H31="","",IF(G31=H31,1,0)) -> 1
A32: Pilot (pre-Phase 29) | B32: T02 | C32: Squat | D32: 4 | E32: 83 | G32: Correct | H32: Correct | J32: =IF(H32="","",IF(H32="Incorrect",IF(G32="Incorrect","TP","FN"),IF(G32="Incorrect","FP","TN"))) -> TN | K32: =IF(H32="","",IF(G32=H32,1,0)) -> 1
A33: Pilot (pre-Phase 29) | B33: T02 | C33: Squat | D33: 5 | E33: 80.4 | G33: Correct | H33: Correct | J33: =IF(H33="","",IF(H33="Incorrect",IF(G33="Incorrect","TP","FN"),IF(G33="Incorrect","FP","TN"))) -> TN | K33: =IF(H33="","",IF(G33=H33,1,0)) -> 1
A34: Pilot (pre-Phase 29) | B34: T02 | C34: Squat | D34: 6 | E34: 89.8 | G34: Correct | H34: Correct | J34: =IF(H34="","",IF(H34="Incorrect",IF(G34="Incorrect","TP","FN"),IF(G34="Incorrect","FP","TN"))) -> TN | K34: =IF(H34="","",IF(G34=H34,1,0)) -> 1
A35: Pilot (pre-Phase 29) | B35: T02 | C35: Squat | D35: 7 | E35: 38.8 | G35: Incorrect | H35: Incorrect | I35: too_deep | J35: =IF(H35="","",IF(H35="Incorrect",IF(G35="Incorrect","TP","FN"),IF(G35="Incorrect","FP","TN"))) -> TP | K35: =IF(H35="","",IF(G35=H35,1,0)) -> 1
A36: Pilot (pre-Phase 29) | B36: T02 | C36: Squat | D36: 8 | E36: 40.1 | G36: Incorrect | H36: Incorrect | I36: too_deep | J36: =IF(H36="","",IF(H36="Incorrect",IF(G36="Incorrect","TP","FN"),IF(G36="Incorrect","FP","TN"))) -> TP | K36: =IF(H36="","",IF(G36=H36,1,0)) -> 1
A37: Pilot (pre-Phase 29) | B37: T02 | C37: Squat | D37: 9 | E37: 45.5 | G37: Incorrect | H37: Incorrect | I37: too_deep | J37: =IF(H37="","",IF(H37="Incorrect",IF(G37="Incorrect","TP","FN"),IF(G37="Incorrect","FP","TN"))) -> TP | K37: =IF(H37="","",IF(G37=H37,1,0)) -> 1
A38: Pilot (pre-Phase 29) | B38: T02 | C38: Squat | D38: 10 | E38: 42.8 | G38: Incorrect | H38: Incorrect | I38: too_deep | J38: =IF(H38="","",IF(H38="Incorrect",IF(G38="Incorrect","TP","FN"),IF(G38="Incorrect","FP","TN"))) -> TP | K38: =IF(H38="","",IF(G38=H38,1,0)) -> 1
A39: Pilot (pre-Phase 29) | B39: T03 | C39: Squat | D39: 1 | E39: 76.1 | G39: Incorrect | H39: Correct | J39: =IF(H39="","",IF(H39="Incorrect",IF(G39="Incorrect","TP","FN"),IF(G39="Incorrect","FP","TN"))) -> FP | K39: =IF(H39="","",IF(G39=H39,1,0)) -> 0
A40: Pilot (pre-Phase 29) | B40: T03 | C40: Squat | D40: 2 | E40: 99.8 | G40: Correct | H40: Correct | J40: =IF(H40="","",IF(H40="Incorrect",IF(G40="Incorrect","TP","FN"),IF(G40="Incorrect","FP","TN"))) -> TN | K40: =IF(H40="","",IF(G40=H40,1,0)) -> 1
...

Sheet Issues & To Do
A1: Data issues and remaining work
A3: Priority | B3: Item | C3: Detail / action
A4: CRITICAL | B4: Pilot data was produced by the OLD analyser | C4: Squat lines have 5 fields (no trunk lean), and deep squats (<80°) were judged wrong. The current Phase 29 code logs 6 fields for squats, removed the "too deep" fault, and now treats parallel-or-deeper (≤80°) as correct. Under today's rules most of the squat "wrong" reps would be correct form. Report this round as a PILOT, then re-run on the Phase 29 build.
A5: HIGH | B5: Push-up Tester 2 has no data | C5: The heading was pasted with no VALIDATION lines. Re-record.
A6: HIGH | B6: Push-up Tester 3 ground truth assumed | C6: No set note was given; assumed first 5 correct, last 5 wrong (same as T01). Reps 8-10 were "wrong" but body line was 168-171° (straight), so the tester may have done a fault the app does not measure. Confirm what T03 actually did.
A7: MEDIUM | B7: Fault type not recorded for push-ups | C7: Note which fault each "wrong" set used (hips_sag, hips_pike, shallow). Needed for the fault-type breakdown.
A8: MEDIUM | B8: Missing squat reps | C8: T01 log starts at rep 3, T02 at rep 1 missing. Either the copy was cut off or the app did not count them. If not counted, record as missed reps (rep detection rate).
A9: LOW | B9: Squat T01 rep 3 | C9: Labelled correct but knee angle 33.2° is very deep. Check whether it was a warm-up or mislabelled.
A10: LOW | B10: Squat T01 rep 9 | C10: Line was truncated ("LIDATION|...") when copied; values kept. Using capture.py avoids copy-paste errors.
A11: TODO | B11: Re-run squat + push-up on the Phase 29 build | C11: Faults to use now: squat = shallow (stop around 90-110°) and excessive forward lean; push-up = shallow (elbow 100-120°), hips_sag, hips_pike.
A12: TODO | B12: Deadlift | C12: No data yet. Phase 29 deadlift still has no failure condition beyond depth (no spine landmarks), so state it as a limitation or add a lockout/depth fault test.
A13: TODO | B13: Reach sample size | C13: ≥ 3 testers × 20 reps per exercise (10 correct + 10 wrong). Current pilot: push-up 20 scored reps, squat 27.
A14: TODO | B14: Use capture.py for the real round | C14: It labels each set live and writes the CSV, so no copy-paste and no assumed labels.
A16: Legend
A17: Blue text | B17: Values typed in from the logs or your notes
A18: Yellow fill | B18: Ground truth: edit here if a label is wrong; every metric recalculates
A19: Black text | B19: Formulas: do not overwrite
