Workbook

Sheet Summary
A1: Posture Detection Accuracy: Final Round
A2: 5 testers × 3 sets × 10 reps per exercise · Phase 29 analyser · collected 13–14 Oct 2026 with capture.py
A4: Settings
A5: Target accuracy | B5: 0.75 | C5: Objective 2 (revised from 90% in the proposal)
A6: z for 95% CI | B6: 1.96 | C6: Wilson score interval
A7: Squat depth: correct if knee ≤ | B7: 80 | C7: FormThresholds.squatDepthMax
A8: Squat trunk lean: correct if ≤ | B8: 57 | C8: FormThresholds.squatTrunkLeanMax
A9: Push-up depth: correct if elbow ≤ | B9: 100 | C9: FormThresholds (push-up correct depth)
A10: Push-up body line: correct if ≥ | B10: 160 | C10: FormThresholds (body line)
A12: Main result (verdict by code rule vs. ground truth)
A13: Exercise | B13: Testers | C13: Reps | D13: TP | E13: TN | F13: FP | G13: FN | H13: Accuracy | I13: 95% CI low | J13: 95% CI high | K13: Precision | L13: Recall | M13: Specificity | N13: F1 | O13: Meets target?
A14: Push-up | B14: 5 | C14: =SUM(D14:G14) -> 150 | D14: =COUNTIFS('Raw Data'!$L$2:$L$301,"TP",'Raw Data'!$B$2:$B$301,$A14) -> 80 | E14: =COUNTIFS('Raw Data'!$L$2:$L$301,"TN",'Raw Data'!$B$2:$B$301,$A14) -> 70 | F14: =COUNTIFS('Raw Data'!$L$2:$L$301,"FP",'Raw Data'!$B$2:$B$301,$A14) -> 0 | G14: =COUNTIFS('Raw Data'!$L$2:$L$301,"FN",'Raw Data'!$B$2:$B$301,$A14) -> 0 | H14: =IF(C14=0,"",(D14+E14)/C14) -> 1 | I14: =IF(C14=0,"",(H14+$B$6^2/(2*C14)-$B$6*SQRT(H14*(1-H14)/C14+$B$6^2/(4*C14^2)))/(1+$B$6^2/C14)) -> 0.97502886 | J14: =IF(C14=0,"",(H14+$B$6^2/(2*C14)+$B$6*SQRT(H14*(1-H14)/C14+$B$6^2/(4*C14^2)))/(1+$B$6^2/C14)) -> 1 | K14: =IF(D14+F14=0,"",D14/(D14+F14)) -> 1 | L14: =IF(D14+G14=0,"",D14/(D14+G14)) -> 1 | M14: =IF(E14+F14=0,"",E14/(E14+F14)) -> 1 | N14: =IF(OR(K14="",L14=""),"",IF(K14+L14=0,0,2*K14*L14/(K14+L14))) -> 1 | O14: =IF(H14="","",IF(H14>=$B$5,"Yes","No")) -> Yes
A15: Squat | B15: 5 | C15: =SUM(D15:G15) -> 150 | D15: =COUNTIFS('Raw Data'!$L$2:$L$301,"TP",'Raw Data'!$B$2:$B$301,$A15) -> 69 | E15: =COUNTIFS('Raw Data'!$L$2:$L$301,"TN",'Raw Data'!$B$2:$B$301,$A15) -> 68 | F15: =COUNTIFS('Raw Data'!$L$2:$L$301,"FP",'Raw Data'!$B$2:$B$301,$A15) -> 9 | G15: =COUNTIFS('Raw Data'!$L$2:$L$301,"FN",'Raw Data'!$B$2:$B$301,$A15) -> 4 | H15: =IF(C15=0,"",(D15+E15)/C15) -> 0.91333333 | I15: =IF(C15=0,"",(H15+$B$6^2/(2*C15)-$B$6*SQRT(H15*(1-H15)/C15+$B$6^2/(4*C15^2)))/(1+$B$6^2/C15)) -> 0.85737055 | J15: =IF(C15=0,"",(H15+$B$6^2/(2*C15)+$B$6*SQRT(H15*(1-H15)/C15+$B$6^2/(4*C15^2)))/(1+$B$6^2/C15)) -> 0.94865331 | K15: =IF(D15+F15=0,"",D15/(D15+F15)) -> 0.88461538 | L15: =IF(D15+G15=0,"",D15/(D15+G15)) -> 0.94520548 | M15: =IF(E15+F15=0,"",E15/(E15+F15)) -> 0.88311688 | N15: =IF(OR(K15="",L15=""),"",IF(K15+L15=0,0,2*K15*L15/(K15+L15))) -> 0.91390728 | O15: =IF(H15="","",IF(H15>=$B$5,"Yes","No")) -> Yes
A16: OVERALL | B16: 5 | C16: =SUM(D16:G16) -> 300 | D16: =COUNTIFS('Raw Data'!$L$2:$L$301,"TP") -> 149 | E16: =COUNTIFS('Raw Data'!$L$2:$L$301,"TN") -> 138 | F16: =COUNTIFS('Raw Data'!$L$2:$L$301,"FP") -> 9 | G16: =COUNTIFS('Raw Data'!$L$2:$L$301,"FN") -> 4 | H16: =IF(C16=0,"",(D16+E16)/C16) -> 0.95666667 | I16: =IF(C16=0,"",(H16+$B$6^2/(2*C16)-$B$6*SQRT(H16*(1-H16)/C16+$B$6^2/(4*C16^2)))/(1+$B$6^2/C16)) -> 0.92728187 | J16: =IF(C16=0,"",(H16+$B$6^2/(2*C16)+$B$6*SQRT(H16*(1-H16)/C16+$B$6^2/(4*C16^2)))/(1+$B$6^2/C16)) -> 0.9745038 | K16: =IF(D16+F16=0,"",D16/(D16+F16)) -> 0.94303797 | L16: =IF(D16+G16=0,"",D16/(D16+G16)) -> 0.97385621 | M16: =IF(E16+F16=0,"",E16/(E16+F16)) -> 0.93877551 | N16: =IF(OR(K16="",L16=""),"",IF(K16+L16=0,0,2*K16*L16/(K16+L16))) -> 0.95819936 | O16: =IF(H16="","",IF(H16>=$B$5,"Yes","No")) -> Yes
A17: Positive class = INCORRECT form. Recall = share of bad reps the app caught. Specificity = share of good reps it correctly passed.
A19: Sensitivity check: how much do the data issues move the result?
A20: Scenario | B20: Push-up | C20: Squat | D20: Overall | E20: What it means
A21: Main result (code-rule verdict) | B21: =SUMIFS('Raw Data'!$M$2:$M$301,'Raw Data'!$B$2:$B$301,"Push-up")/COUNTIFS('Raw Data'!$B$2:$B$301,"Push-up") -> 1 | C21: =SUMIFS('Raw Data'!$M$2:$M$301,'Raw Data'!$B$2:$B$301,"Squat")/COUNTIFS('Raw Data'!$B$2:$B$301,"Squat") -> 0.91333333 | D21: =SUM('Raw Data'!$M$2:$M$301)/COUNTA('Raw Data'!$A$2:$A$301) -> 0.95666667 | E21: Uses the verdict the code produces from the logged angles.
A22: Verdicts exactly as logged | B22: =SUMIFS('Raw Data'!$N$2:$N$301,'Raw Data'!$B$2:$B$301,"Push-up")/COUNTIFS('Raw Data'!$B$2:$B$301,"Push-up") -> 1 | C22: =SUMIFS('Raw Data'!$N$2:$N$301,'Raw Data'!$B$2:$B$301,"Squat")/COUNTIFS('Raw Data'!$B$2:$B$301,"Squat") -> 0.94 | D22: =SUM('Raw Data'!$N$2:$N$301)/COUNTA('Raw Data'!$A$2:$A$301) -> 0.97 | E22: Includes the 4 squat verdicts that were changed in Excel.
A23: Ignoring every observer flip | B23: =SUMIFS('Raw Data'!$O$2:$O$301,'Raw Data'!$B$2:$B$301,"Push-up")/COUNTIFS('Raw Data'!$B$2:$B$301,"Push-up") -> 1 | C23: =SUMIFS('Raw Data'!$O$2:$O$301,'Raw Data'!$B$2:$B$301,"Squat")/COUNTIFS('Raw Data'!$B$2:$B$301,"Squat") -> 0.88 | D23: =SUM('Raw Data'!$O$2:$O$301)/COUNTA('Raw Data'!$A$2:$A$301) -> 0.94 | E23: Uses the label set before each rep. All 5 net flips moved the label towards the app's verdict.
A26: Confusion matrix: Push-up
B27: Predicted Correct | C27: Predicted Incorrect | D27: Total
A28: Actual Correct | B28: =E14 -> 70 | C28: =F14 -> 0 | D28: =B28+C28 -> 70
A29: Actual Incorrect | B29: =G14 -> 0 | C29: =D14 -> 80 | D29: =B29+C29 -> 80
A31: Confusion matrix: Squat
B32: Predicted Correct | C32: Predicted Incorrect | D32: Total
A33: Actual Correct | B33: =E15 -> 68 | C33: =F15 -> 9 | D33: =B33+C33 -> 77
A34: Actual Incorrect | B34: =G15 -> 4 | C34: =D15 -> 69 | D34: =B34+C34 -> 73
A36: Accuracy by tester
A37: Exercise | B37: Tester | C37: Reps | D37: Matches | E37: Accuracy | F37: Correct-form reps | G37: Incorrect-form reps
A38: Push-up | B38: T01 | C38: =COUNTIFS('Raw Data'!$B$2:$B$301,A38,'Raw Data'!$A$2:$A$301,B38) -> 30 | D38: =SUMIFS('Raw Data'!$M$2:$M$301,'Raw Data'!$B$2:$B$301,A38,'Raw Data'!$A$2:$A$301,B38) -> 30 | E38: =IF(C38=0,"",D38/C38) -> 1 | F38: =COUNTIFS('Raw Data'!$B$2:$B$301,A38,'Raw Data'!$A$2:$A$301,B38,'Raw Data'!$I$2:$I$301,"Correct") -> 0 | G38: =COUNTIFS('Raw Data'!$B$2:$B$301,A38,'Raw Data'!$A$2:$A$301,B38,'Raw Data'!$I$2:$I$301,"Incorrect") -> 30
A39: Push-up | B39: T02 | C39: =COUNTIFS('Raw Data'!$B$2:$B$301,A39,'Raw Data'!$A$2:$A$301,B39) -> 30 | D39: =SUMIFS('Raw Data'!$M$2:$M$301,'Raw Data'!$B$2:$B$301,A39,'Raw Data'!$A$2:$A$301,B39) -> 30 | E39: =IF(C39=0,"",D39/C39) -> 1 | F39: =COUNTIFS('Raw Data'!$B$2:$B$301,A39,'Raw Data'!$A$2:$A$301,B39,'Raw Data'!$I$2:$I$301,"Correct") -> 20 | G39: =COUNTIFS('Raw Data'!$B$2:$B$301,A39,'Raw Data'!$A$2:$A$301,B39,'Raw Data'!$I$2:$I$301,"Incorrect") -> 10
A40: Push-up | B40: T03 | C40: =COUNTIFS('Raw Data'!$B$2:$B$301,A40,'Raw Data'!$A$2:$A$301,B40) -> 30 | D40: =SUMIFS('Raw Data'!$M$2:$M$301,'Raw Data'!$B$2:$B$301,A40,'Raw Data'!$A$2:$A$301,B40) -> 30 | E40: =IF(C40=0,"",D40/C40) -> 1 | F40: =COUNTIFS('Raw Data'!$B$2:$B$301,A40,'Raw Data'!$A$2:$A$301,B40,'Raw Data'!$I$2:$I$301,"Correct") -> 30 | G40: =COUNTIFS('Raw Data'!$B$2:$B$301,A40,'Raw Data'!$A$2:$A$301,B40,'Raw Data'!$I$2:$I$301,"Incorrect") -> 0
A41: Push-up | B41: T04 | C41: =COUNTIFS('Raw Data'!$B$2:$B$301,A41,'Raw Data'!$A$2:$A$301,B41) -> 30 | D41: =SUMIFS('Raw Data'!$M$2:$M$301,'Raw Data'!$B$2:$B$301,A41,'Raw Data'!$A$2:$A$301,B41) -> 30 | E41: =IF(C41=0,"",D41/C41) -> 1 | F41: =COUNTIFS('Raw Data'!$B$2:$B$301,A41,'Raw Data'!$A$2:$A$301,B41,'Raw Data'!$I$2:$I$301,"Correct") -> 10 | G41: =COUNTIFS('Raw Data'!$B$2:$B$301,A41,'Raw Data'!$A$2:$A$301,B41,'Raw Data'!$I$2:$I$301,"Incorrect") -> 20
A42: Push-up | B42: T05 | C42: =COUNTIFS('Raw Data'!$B$2:$B$301,A42,'Raw Data'!$A$2:$A$301,B42) -> 30 | D42: =SUMIFS('Raw Data'!$M$2:$M$301,'Raw Data'!$B$2:$B$301,A42,'Raw Data'!$A$2:$A$301,B42) -> 30 | E42: =IF(C42=0,"",D42/C42) -> 1 | F42: =COUNTIFS('Raw Data'!$B$2:$B$301,A42,'Raw Data'!$A$2:$A$301,B42,'Raw Data'!$I$2:$I$301,"Correct") -> 10 | G42: =COUNTIFS('Raw Data'!$B$2:$B$301,A42,'Raw Data'!$A$2:$A$301,B42,'Raw Data'!$I$2:$I$301,"Incorrect") -> 20
A43: Squat | B43: T01 | C43: =COUNTIFS('Raw Data'!$B$2:$B$301,A43,'Raw Data'!$A$2:$A$301,B43) -> 30 | D43: =SUMIFS('Raw Data'!$M$2:$M$301,'Raw Data'!$B$2:$B$301,A43,'Raw Data'!$A$2:$A$301,B43) -> 27 | E43: =IF(C43=0,"",D43/C43) -> 0.9 | F43: =COUNTIFS('Raw Data'!$B$2:$B$301,A43,'Raw Data'!$A$2:$A$301,B43,'Raw Data'!$I$2:$I$301,"Correct") -> 19 | G43: =COUNTIFS('Raw Data'!$B$2:$B$301,A43,'Raw Data'!$A$2:$A$301,B43,'Raw Data'!$I$2:$I$301,"Incorrect") -> 11
A44: Squat | B44: T02 | C44: =COUNTIFS('Raw Data'!$B$2:$B$301,A44,'Raw Data'!$A$2:$A$301,B44) -> 30 | D44: =SUMIFS('Raw Data'!$M$2:$M$301,'Raw Data'!$B$2:$B$301,A44,'Raw Data'!$A$2:$A$301,B44) -> 22 | E44: =IF(C44=0,"",D44/C44) -> 0.73333333 | F44: =COUNTIFS('Raw Data'!$B$2:$B$301,A44,'Raw Data'!$A$2:$A$301,B44,'Raw Data'!$I$2:$I$301,"Correct") -> 20 | G44: =COUNTIFS('Raw Data'!$B$2:$B$301,A44,'Raw Data'!$A$2:$A$301,B44,'Raw Data'!$I$2:$I$301,"Incorrect") -> 10
A45: Squat | B45: T03 | C45: =COUNTIFS('Raw Data'!$B$2:$B$301,A45,'Raw Data'!$A$2:$A$301,B45) -> 30 | D45: =SUMIFS('Raw Data'!$M$2:$M$301,'Raw Data'!$B$2:$B$301,A45,'Raw Data'!$A$2:$A$301,B45) -> 30 | E45: =IF(C45=0,"",D45/C45) -> 1 | F45: =COUNTIFS('Raw Data'!$B$2:$B$301,A45,'Raw Data'!$A$2:$A$301,B45,'Raw Data'!$I$2:$I$301,"Correct") -> 18 | G45: =COUNTIFS('Raw Data'!$B$2:$B$301,A45,'Raw Data'!$A$2:$A$301,B45,'Raw Data'!$I$2:$I$301,"Incorrect") -> 12
A46: Squat | B46: T04 | C46: =COUNTIFS('Raw Data'!$B$2:$B$301,A46,'Raw Data'!$A$2:$A$301,B46) -> 30 | D46: =SUMIFS('Raw Data'!$M$2:$M$301,'Raw Data'!$B$2:$B$301,A46,'Raw Data'!$A$2:$A$301,B46) -> 30 | E46: =IF(C46=0,"",D46/C46) -> 1 | F46: =COUNTIFS('Raw Data'!$B$2:$B$301,A46,'Raw Data'!$A$2:$A$301,B46,'Raw Data'!$I$2:$I$301,"Correct") -> 0 | G46: =COUNTIFS('Raw Data'!$B$2:$B$301,A46,'Raw Data'!$A$2:$A$301,B46,'Raw Data'!$I$2:$I$301,"Incorrect") -> 30
A47: Squat | B47: T05 | C47: =COUNTIFS('Raw Data'!$B$2:$B$301,A47,'Raw Data'!$A$2:$A$301,B47) -> 30 | D47: =SUMIFS('Raw Data'!$M$2:$M$301,'Raw Data'!$B$2:$B$301,A47,'Raw Data'!$A$2:$A$301,B47) -> 28 | E47: =IF(C47=0,"",D47/C47) -> 0.93333333 | F47: =COUNTIFS('Raw Data'!$B$2:$B$301,A47,'Raw Data'!$A$2:$A$301,B47,'Raw Data'!$I$2:$I$301,"Correct") -> 20 | G47: =COUNTIFS('Raw Data'!$B$2:$B$301,A47,'Raw Data'!$A$2:$A$301,B47,'Raw Data'!$I$2:$I$301,"Incorrect") -> 10

Sheet Raw Data
A1: Tester | B1: Exercise | C1: Set | D1: Rep | E1: Primary angle (°) | F1: Secondary (°) | G1: Logged verdict | H1: Verdict by code rule | I1: Ground truth | J1: Observer flipped? | K1: Label before flip | L1: Outcome | M1: Match | N1: Match (as logged) | O1: Match (no flips) | P1: Notes | Q1: Source file
A2: T01 | B2: Push-up | C2: 1 | D2: 1 | E2: 102.5 | F2: 125 | G2: Incorrect | H2: =IF(B2="Squat",IF(AND(E2<=Summary!$B$7,OR(F2="",F2<=Summary!$B$8)),"Correct","Incorrect"),IF(AND(E2<=Summary!$B$9,OR(F2="",F2>=Summary!$B$10)),"Correct","Incorrect")) -> Incorrect | I2: Incorrect | J2: No | K2: =IF(J2="Yes",IF(I2="Correct","Incorrect","Correct"),I2) -> Incorrect | L2: =IF(I2="Incorrect",IF(H2="Incorrect","TP","FN"),IF(H2="Incorrect","FP","TN")) -> TP | M2: =IF(H2=I2,1,0) -> 1 | N2: =IF(G2=I2,1,0) -> 1 | O2: =IF(H2=K2,1,0) -> 1 | Q2: posture_T01_20261013_164651.csv
A3: T01 | B3: Push-up | C3: 1 | D3: 2 | E3: 58.9 | F3: 126 | G3: Incorrect | H3: =IF(B3="Squat",IF(AND(E3<=Summary!$B$7,OR(F3="",F3<=Summary!$B$8)),"Correct","Incorrect"),IF(AND(E3<=Summary!$B$9,OR(F3="",F3>=Summary!$B$10)),"Correct","Incorrect")) -> Incorrect | I3: Incorrect | J3: No | K3: =IF(J3="Yes",IF(I3="Correct","Incorrect","Correct"),I3) -> Incorrect | L3: =IF(I3="Incorrect",IF(H3="Incorrect","TP","FN"),IF(H3="Incorrect","FP","TN")) -> TP | M3: =IF(H3=I3,1,0) -> 1 | N3: =IF(G3=I3,1,0) -> 1 | O3: =IF(H3=K3,1,0) -> 1 | Q3: posture_T01_20261013_164651.csv
A4: T01 | B4: Push-up | C4: 1 | D4: 3 | E4: 61.4 | F4: 127.3 | G4: Incorrect | H4: =IF(B4="Squat",IF(AND(E4<=Summary!$B$7,OR(F4="",F4<=Summary!$B$8)),"Correct","Incorrect"),IF(AND(E4<=Summary!$B$9,OR(F4="",F4>=Summary!$B$10)),"Correct","Incorrect")) -> Incorrect | I4: Incorrect | J4: No | K4: =IF(J4="Yes",IF(I4="Correct","Incorrect","Correct"),I4) -> Incorrect | L4: =IF(I4="Incorrect",IF(H4="Incorrect","TP","FN"),IF(H4="Incorrect","FP","TN")) -> TP | M4: =IF(H4=I4,1,0) -> 1 | N4: =IF(G4=I4,1,0) -> 1 | O4: =IF(H4=K4,1,0) -> 1 | Q4: posture_T01_20261013_164651.csv
A5: T01 | B5: Push-up | C5: 1 | D5: 4 | E5: 104.1 | F5: 107 | G5: Incorrect | H5: =IF(B5="Squat",IF(AND(E5<=Summary!$B$7,OR(F5="",F5<=Summary!$B$8)),"Correct","Incorrect"),IF(AND(E5<=Summary!$B$9,OR(F5="",F5>=Summary!$B$10)),"Correct","Incorrect")) -> Incorrect | I5: Incorrect | J5: No | K5: =IF(J5="Yes",IF(I5="Correct","Incorrect","Correct"),I5) -> Incorrect | L5: =IF(I5="Incorrect",IF(H5="Incorrect","TP","FN"),IF(H5="Incorrect","FP","TN")) -> TP | M5: =IF(H5=I5,1,0) -> 1 | N5: =IF(G5=I5,1,0) -> 1 | O5: =IF(H5=K5,1,0) -> 1 | Q5: posture_T01_20261013_164651.csv
A6: T01 | B6: Push-up | C6: 1 | D6: 5 | E6: 113.5 | F6: 113.1 | G6: Incorrect | H6: =IF(B6="Squat",IF(AND(E6<=Summary!$B$7,OR(F6="",F6<=Summary!$B$8)),"Correct","Incorrect"),IF(AND(E6<=Summary!$B$9,OR(F6="",F6>=Summary!$B$10)),"Correct","Incorrect")) -> Incorrect | I6: Incorrect | J6: No | K6: =IF(J6="Yes",IF(I6="Correct","Incorrect","Correct"),I6) -> Incorrect | L6: =IF(I6="Incorrect",IF(H6="Incorrect","TP","FN"),IF(H6="Incorrect","FP","TN")) -> TP | M6: =IF(H6=I6,1,0) -> 1 | N6: =IF(G6=I6,1,0) -> 1 | O6: =IF(H6=K6,1,0) -> 1 | Q6: posture_T01_20261013_164651.csv
A7: T01 | B7: Push-up | C7: 1 | D7: 6 | E7: 65 | F7: 134 | G7: Incorrect | H7: =IF(B7="Squat",IF(AND(E7<=Summary!$B$7,OR(F7="",F7<=Summary!$B$8)),"Correct","Incorrect"),IF(AND(E7<=Summary!$B$9,OR(F7="",F7>=Summary!$B$10)),"Correct","Incorrect")) -> Incorrect | I7: Incorrect | J7: No | K7: =IF(J7="Yes",IF(I7="Correct","Incorrect","Correct"),I7) -> Incorrect | L7: =IF(I7="Incorrect",IF(H7="Incorrect","TP","FN"),IF(H7="Incorrect","FP","TN")) -> TP | M7: =IF(H7=I7,1,0) -> 1 | N7: =IF(G7=I7,1,0) -> 1 | O7: =IF(H7=K7,1,0) -> 1 | Q7: posture_T01_20261013_164651.csv
A8: T01 | B8: Push-up | C8: 1 | D8: 7 | E8: 65.6 | F8: 129 | G8: Incorrect | H8: =IF(B8="Squat",IF(AND(E8<=Summary!$B$7,OR(F8="",F8<=Summary!$B$8)),"Correct","Incorrect"),IF(AND(E8<=Summary!$B$9,OR(F8="",F8>=Summary!$B$10)),"Correct","Incorrect")) -> Incorrect | I8: Incorrect | J8: No | K8: =IF(J8="Yes",IF(I8="Correct","Incorrect","Correct"),I8) -> Incorrect | L8: =IF(I8="Incorrect",IF(H8="Incorrect","TP","FN"),IF(H8="Incorrect","FP","TN")) -> TP | M8: =IF(H8=I8,1,0) -> 1 | N8: =IF(G8=I8,1,0) -> 1 | O8: =IF(H8=K8,1,0) -> 1 | Q8: posture_T01_20261013_164651.csv
A9: T01 | B9: Push-up | C9: 1 | D9: 8 | E9: 64.6 | F9: 129.4 | G9: Incorrect | H9: =IF(B9="Squat",IF(AND(E9<=Summary!$B$7,OR(F9="",F9<=Summary!$B$8)),"Correct","Incorrect"),IF(AND(E9<=Summary!$B$9,OR(F9="",F9>=Summary!$B$10)),"Correct","Incorrect")) -> Incorrect | I9: Incorrect | J9: No | K9: =IF(J9="Yes",IF(I9="Correct","Incorrect","Correct"),I9) -> Incorrect | L9: =IF(I9="Incorrect",IF(H9="Incorrect","TP","FN"),IF(H9="Incorrect","FP","TN")) -> TP | M9: =IF(H9=I9,1,0) -> 1 | N9: =IF(G9=I9,1,0) -> 1 | O9: =IF(H9=K9,1,0) -> 1 | Q9: posture_T01_20261013_164651.csv
A10: T01 | B10: Push-up | C10: 1 | D10: 9 | E10: 64.5 | F10: 128.6 | G10: Incorrect | H10: =IF(B10="Squat",IF(AND(E10<=Summary!$B$7,OR(F10="",F10<=Summary!$B$8)),"Correct","Incorrect"),IF(AND(E10<=Summary!$B$9,OR(F10="",F10>=Summary!$B$10)),"Correct","Incorrect")) -> Incorrect | I10: Incorrect | J10: No | K10: =IF(J10="Yes",IF(I10="Correct","Incorrect","Correct"),I10) -> Incorrect | L10: =IF(I10="Incorrect",IF(H10="Incorrect","TP","FN"),IF(H10="Incorrect","FP","TN")) -> TP | M10: =IF(H10=I10,1,0) -> 1 | N10: =IF(G10=I10,1,0) -> 1 | O10: =IF(H10=K10,1,0) -> 1 | Q10: posture_T01_20261013_164651.csv
A11: T01 | B11: Push-up | C11: 1 | D11: 10 | E11: 61.7 | F11: 124.3 | G11: Incorrect | H11: =IF(B11="Squat",IF(AND(E11<=Summary!$B$7,OR(F11="",F11<=Summary!$B$8)),"Correct","Incorrect"),IF(AND(E11<=Summary!$B$9,OR(F11="",F11>=Summary!$B$10)),"Correct","Incorrect")) -> Incorrect | I11: Incorrect | J11: No | K11: =IF(J11="Yes",IF(I11="Correct","Incorrect","Correct"),I11) -> Incorrect | L11: =IF(I11="Incorrect",IF(H11="Incorrect","TP","FN"),IF(H11="Incorrect","FP","TN")) -> TP | M11: =IF(H11=I11,1,0) -> 1 | N11: =IF(G11=I11,1,0) -> 1 | O11: =IF(H11=K11,1,0) -> 1 | Q11: posture_T01_20261013_164651.csv
A12: T01 | B12: Push-up | C12: 2 | D12: 1 | E12: 58.8 | F12: 121.6 | G12: Incorrect | H12: =IF(B12="Squat",IF(AND(E12<=Summary!$B$7,OR(F12="",F12<=Summary!$B$8)),"Correct","Incorrect"),IF(AND(E12<=Summary!$B$9,OR(F12="",F12>=Summary!$B$10)),"Correct","Incorrect")) -> Incorrect | I12: Incorrect | J12: No | K12: =IF(J12="Yes",IF(I12="Correct","Incorrect","Correct"),I12) -> Incorrect | L12: =IF(I12="Incorrect",IF(H12="Incorrect","TP","FN"),IF(H12="Incorrect","FP","TN")) -> TP | M12: =IF(H12=I12,1,0) -> 1 | N12: =IF(G12=I12,1,0) -> 1 | O12: =IF(H12=K12,1,0) -> 1 | Q12: posture_T01_20261013_164651.csv
A13: T01 | B13: Push-up | C13: 2 | D13: 2 | E13: 58.7 | F13: 118.6 | G13: Incorrect | H13: =IF(B13="Squat",IF(AND(E13<=Summary!$B$7,OR(F13="",F13<=Summary!$B$8)),"Correct","Incorrect"),IF(AND(E13<=Summary!$B$9,OR(F13="",F13>=Summary!$B$10)),"Correct","Incorrect")) -> Incorrect | I13: Incorrect | J13: No | K13: =IF(J13="Yes",IF(I13="Correct","Incorrect","Correct"),I13) -> Incorrect | L13: =IF(I13="Incorrect",IF(H13="Incorrect","TP","FN"),IF(H13="Incorrect","FP","TN")) -> TP | M13: =IF(H13=I13,1,0) -> 1 | N13: =IF(G13=I13,1,0) -> 1 | O13: =IF(H13=K13,1,0) -> 1 | Q13: posture_T01_20261013_164651.csv
... A163: T01 | B163: Squat | C163: 2 | D163: 2 | E163: 82 | F163: 31.8 | G163: Incorrect | H163: =IF(B163="Squat",IF(AND(E163<=Summary!$B$7,OR(F163="",F163<=Summary!$B$8)),"Correct","Incorrect"),IF(AND(E163<=Summary!$B$9,OR(F163="",F163>=Summary!$B$10)),"Correct","Incorrect")) -> Incorrect | I163: Correct | J163: No | K163: =IF(J163="Yes",IF(I163="Correct","Incorrect","Correct"),I163) -> Correct | L163: =IF(I163="Incorrect",IF(H163="Incorrect","TP","FN"),IF(H163="Incorrect","FP","TN")) -> FP | M163: =IF(H163=I163,1,0) -> 0 | N163: =IF(G163=I163,1,0) -> 0 | O163: =IF(H163=K163,1,0) -> 0 | Q163: posture_T01_20261013_165543.csv
A164: T01 | B164: Squat | C164: 2 | D164: 3 | E164: 90.6 | F164: 26.1 | G164: Incorrect | H164: =IF(B164="Squat",IF(AND(E164<=Summary!$B$7,OR(F164="",F164<=Summary!$B$8)),"Correct","Incorrect"),IF(AND(E164<=Summary!$B$9,OR(F164="",F164>=Summary!$B$10)),"Correct","Incorrect")) -> Incorrect | I164: Incorrect | J164: Yes | K164: =IF(J164="Yes",IF(I164="Correct","Incorrect","Correct"),I164) -> Correct | L164: =IF(I164="Incorrect",IF(H164="Incorrect","TP","FN"),IF(H164="Incorrect","FP","TN")) -> TP | M164: =IF(H164=I164,1,0) -> 1 | N164: =IF(G164=I164,1,0) -> 1 | O164: =IF(H164=K164,1,0) -> 0 | P164: Observer flipped the label | Q164: posture_T01_20261013_165543.csv
A165: T01 | B165: Squat | C165: 2 | D165: 4 | E165: 76.8 | F165: 33.1 | G165: Correct | H165: =IF(B165="Squat",IF(AND(E165<=Summary!$B$7,OR(F165="",F165<=Summary!$B$8)),"Correct","Incorrect"),IF(AND(E165<=Summary!$B$9,OR(F165="",F165>=Summary!$B$10)),"Correct","Incorrect")) -> Correct | I165: Correct | J165: No | K165: =IF(J165="Yes",IF(I165="Correct","Incorrect","Correct"),I165) -> Correct | L165: =IF(I165="Incorrect",IF(H165="Incorrect","TP","FN"),IF(H165="Incorrect","FP","TN")) -> TN | M165: =IF(H165=I165,1,0) -> 1 | N165: =IF(G165=I165,1,0) -> 1 | O165: =IF(H165=K165,1,0) -> 1 | Q165: posture_T01_20261013_165543.csv
A166: T01 | B166: Squat | C166: 2 | D166: 5 | E166: 73.7 | F166: 28.4 | G166: Correct | H166: =IF(B166="Squat",IF(AND(E166<=Summary!$B$7,OR(F166="",F166<=Summary!$B$8)),"Correct","Incorrect"),IF(AND(E166<=Summary!$B$9,OR(F166="",F166>=Summary!$B$10)),"Correct","Incorrect")) -> Correct | I166: Correct | J166: No | K166: =IF(J166="Yes",IF(I166="Correct","Incorrect","Correct"),I166) -> Correct | L166: =IF(I166="Incorrect",IF(H166="Incorrect","TP","FN"),IF(H166="Incorrect","FP","TN")) -> TN | M166: =IF(H166=I166,1,0) -> 1 | N166: =IF(G166=I166,1,0) -> 1 | O166: =IF(H166=K166,1,0) -> 1 | Q166: posture_T01_20261013_165543.csv
A167: T01 | B167: Squat | C167: 2 | D167: 6 | E167: 73.5 | F167: 29.7 | G167: Correct | H167: =IF(B167="Squat",IF(AND(E167<=Summary!$B$7,OR(F167="",F167<=Summary!$B$8)),"Correct","Incorrect"),IF(AND(E167<=Summary!$B$9,OR(F167="",F167>=Summary!$B$10)),"Correct","Incorrect")) -> Correct | I167: Correct | J167: No | K167: =IF(J167="Yes",IF(I167="Correct","Incorrect","Correct"),I167) -> Correct | L167: =IF(I167="Incorrect",IF(H167="Incorrect","TP","FN"),IF(H167="Incorrect","FP","TN")) -> TN | M167: =IF(H167=I167,1,0) -> 1 | N167: =IF(G167=I167,1,0) -> 1 | O167: =IF(H167=K167,1,0) -> 1 | Q167: posture_T01_20261013_165543.csv
A168: T01 | B168: Squat | C168: 2 | D168: 7 | E168: 73.1 | F168: 29.2 | G168: Correct | H168: =IF(B168="Squat",IF(AND(E168<=Summary!$B$7,OR(F168="",F168<=Summary!$B$8)),"Correct","Incorrect"),IF(AND(E168<=Summary!$B$9,OR(F168="",F168>=Summary!$B$10)),"Correct","Incorrect")) -> Correct | I168: Correct | J168: No | K168: =IF(J168="Yes",IF(I168="Correct","Incorrect","Correct"),I168) -> Correct | L168: =IF(I168="Incorrect",IF(H168="Incorrect","TP","FN"),IF(H168="Incorrect","FP","TN")) -> TN | M168: =IF(H168=I168,1,0) -> 1 | N168: =IF(G168=I168,1,0) -> 1 | O168: =IF(H168=K168,1,0) -> 1 | Q168: posture_T01_20261013_165543.csv
A169: T01 | B169: Squat | C169: 2 | D169: 8 | E169: 73.2 | F169: 29.9 | G169: Correct | H169: =IF(B169="Squat",IF(AND(E169<=Summary!$B$7,OR(F169="",F169<=Summary!$B$8)),"Correct","Incorrect"),IF(AND(E169<=Summary!$B$9,OR(F169="",F169>=Summary!$B$10)),"Correct","Incorrect")) -> Correct | I169: Correct | J169: No | K169: =IF(J169="Yes",IF(I169="Correct","Incorrect","Correct"),I169) -> Correct | L169: =IF(I169="Incorrect",IF(H169="Incorrect","TP","FN"),IF(H169="Incorrect","FP","TN")) -> TN | M169: =IF(H169=I169,1,0) -> 1 | N169: =IF(G169=I169,1,0) -> 1 | O169: =IF(H169=K169,1,0) -> 1 | Q169: posture_T01_20261013_165543.csv
A170: T01 | B170: Squat | C170: 2 | D170: 9 | E170: 72.9 | F170: 30.4 | G170: Correct | H170: =IF(B170="Squat",IF(AND(E170<=Summary!$B$7,OR(F170="",F170<=Summary!$B$8)),"Correct","Incorrect"),IF(AND(E170<=Summary!$B$9,OR(F170="",F170>=Summary!$B$10)),"Correct","Incorrect")) -> Correct | I170: Correct | J170: No | K170: =IF(J170="Yes",IF(I170="Correct","Incorrect","Correct"),I170) -> Correct | L170: =IF(I170="Incorrect",IF(H170="Incorrect","TP","FN"),IF(H170="Incorrect","FP","TN")) -> TN | M170: =IF(H170=I170,1,0) -> 1 | N170: =IF(G170=I170,1,0) -> 1 | O170: =IF(H170=K170,1,0) -> 1 | Q170: posture_T01_20261013_165543.csv
A171: T01 | B171: Squat | C171: 2 | D171: 10 | E171: 71.1 | F171: 31.1 | G171: Correct | H171: =IF(B171="Squat",IF(AND(E171<=Summary!$B$7,OR(F171="",F171<=Summary!$B$8)),"Correct","Incorrect"),IF(AND(E171<=Summary!$B$9,OR(F171="",F171>=Summary!$B$10)),"Correct","Incorrect")) -> Correct | I171: Correct | J171: No | K171: =IF(J171="Yes",IF(I171="Correct","Incorrect","Correct"),I171) -> Correct | L171: =IF(I171="Incorrect",IF(H171="Incorrect","TP","FN"),IF(H171="Incorrect","FP","TN")) -> TN | M171: =IF(H171=I171,1,0) -> 1 | N171: =IF(G171=I171,1,0) -> 1 | O171: =IF(H171=K171,1,0) -> 1 | Q171: posture_T01_20261013_165543.csv
A172: T01 | B172: Squat | C172: 3 | D172: 1 | E172: 104.9 | F172: 21.3 | G172: Incorrect | H172: =IF(B172="Squat",IF(AND(E172<=Summary!$B$7,OR(F172="",F172<=Summary!$B$8)),"Correct","Incorrect"),IF(AND(E172<=Summary!$B$9,OR(F172="",F172>=Summary!$B$10)),"Correct","Incorrect")) -> Incorrect | I172: Incorrect | J172: No | K172: =IF(J172="Yes",IF(I172="Correct","Incorrect","Correct"),I172) -> Incorrect | L172: =IF(I172="Incorrect",IF(H172="Incorrect","TP","FN"),IF(H172="Incorrect","FP","TN")) -> TP | M172: =IF(H172=I172,1,0) -> 1 | N172: =IF(G172=I172,1,0) -> 1 | O172: =IF(H172=K172,1,0) -> 1 | Q172: posture_T01_20261013_165543.csv
A173: T01 | B173: Squat | C173: 3 | D173: 2 | E173: 108.9 | F173: 14.5 | G173: Incorrect | H173: =IF(B173="Squat",IF(AND(E173<=Summary!$B$7,OR(F173="",F173<=Summary!$B$8)),"Correct","Incorrect"),IF(AND(E173<=Summary!$B$9,OR(F173="",F173>=Summary!$B$10)),"Correct","Incorrect")) -> Incorrect | I173: Incorrect | J173: No | K173: =IF(J173="Yes",IF(I173="Correct","Incorrect","Correct"),I173) -> Incorrect | L173: =IF(I173="Incorrect",IF(H173="Incorrect","TP","FN"),IF(H173="Incorrect","FP","TN")) -> TP | M173: =IF(H173=I173,1,0) -> 1 | N173: =IF(G173=I173,1,0) -> 1 | O173: =IF(H173=K173,1,0) -> 1 | Q173: posture_T01_20261013_165543.csv
A174: T01 | B174: Squat | C174: 3 | D174: 3 | E174: 109.9 | F174: 11.9 | G174: Incorrect | H174: =IF(B174="Squat",IF(AND(E174<=Summary!$B$7,OR(F174="",F174<=Summary!$B$8)),"Correct","Incorrect"),IF(AND(E174<=Summary!$B$9,OR(F174="",F174>=Summary!$B$10)),"Correct","Incorrect")) -> Incorrect | I174: Incorrect | J174: No | K174: =IF(J174="Yes",IF(I174="Correct","Incorrect","Correct"),I174) -> Incorrect | L174: =IF(I174="Incorrect",IF(H174="Incorrect","TP","FN"),IF(H174="Incorrect","FP","TN")) -> TP | M174: =IF(H174=I174,1,0) -> 1 | N174: =IF(G174=I174,1,0) -> 1 | O174: =IF(H174=K174,1,0) -> 1 | Q174: posture_T01_20261013_165543.csv
A175: T01 | B175: Squat | C175: 3 | D175: 4 | E175: 102.5 | F175: 13.3 | G175: Incorrect | H175: =IF(B175="Squat",IF(AND(E175<=Summary!$B$7,OR(F175="",F175<=Summary!$B$8)),"Correct","Incorrect"),IF(AND(E175<=Summary!$B$9,OR(F175="",F175>=Summary!$B$10)),"Correct","Incorrect")) -> Incorrect | I175: Incorrect | J175: No | K175: =IF(J175="Yes",IF(I175="Correct","Incorrect","Correct"),I175) -> Incorrect | L175: =IF(I175="Incorrect",IF(H175="Incorrect","TP","FN"),IF(H175="Incorrect","FP","TN")) -> TP | M175: =IF(H175=I175,1,0) -> 1 | N175: =IF(G175=I175,1,0) -> 1 | O175: =IF(H175=K175,1,0) -> 1 | Q175: posture_T01_20261013_165543.csv
A176: T01 | B176: Squat | C176: 3 | D176: 5 | E176: 103.9 | F176: 19.7 | G176: Incorrect | H176: =IF(B176="Squat",IF(AND(E176<=Summary!$B$7,OR(F176="",F176<=Summary!$B$8)),"Correct","Incorrect"),IF(AND(E176<=Summary!$B$9,OR(F176="",F176>=Summary!$B$10)),"Correct","Incorrect")) -> Incorrect | I176: Incorrect | J176: No | K176: =IF(J176="Yes",IF(I176="Correct","Incorrect","Correct"),I176) -> Incorrect | L176: =IF(I176="Incorrect",IF(H176="Incorrect","TP","FN"),IF(H176="Incorrect","FP","TN")) -> TP | M176: =IF(H176=I176,1,0) -> 1 | N176: =IF(G176=I176,1,0) -> 1 | O176: =IF(H176=K176,1,0) -> 1 | Q176: posture_T01_20261013_165543.csv
A177: T01 | B177: Squat | C177: 3 | D177: 6 | E177: 99.9 | F177: 23.1 | G177: Incorrect | H177: =IF(B177="Squat",IF(AND(E177<=Summary!$B$7,OR(F177="",F177<=Summary!$B$8)),"Correct","Incorrect"),IF(AND(E177<=Summary!$B$9,OR(F177="",F177>=Summary!$B$10)),"Correct","Incorrect")) -> Incorrect | I177: Incorrect | J177: No | K177: =IF(J177="Yes",IF(I177="Correct","Incorrect","Correct"),I177) -> Incorrect | L177: =IF(I177="Incorrect",IF(H177="Incorrect","TP","FN"),IF(H177="Incorrect","FP","TN")) -> TP | M177: =IF(H177=I177,1,0) -> 1 | N177: =IF(G177=I177,1,0) -> 1 | O177: =IF(H177=K177,1,0) -> 1 | Q177: posture_T01_20261013_165543.csv
A178: T01 | B178: Squat | C178: 3 | D178: 7 | E178: 70.4 | F178: 32.2 | G178: Correct | H178: =IF(B178="Squat",IF(AND(E178<=Summary!$B$7,OR(F178="",F178<=Summary!$B$8)),"Correct","Incorrect"),IF(AND(E178<=Summary!$B$9,OR(F178="",F178>=Summary!$B$10)),"Correct","Incorrect")) -> Correct | I178: Incorrect | J178: No | K178: =IF(J178="Yes",IF(I178="Correct","Incorrect","Correct"),I178) -> Incorrect | L178: =IF(I178="Incorrect",IF(H178="Incorrect","TP","FN"),IF(H178="Incorrect","FP","TN")) -> FN | M178: =IF(H178=I178,1,0) -> 0 | N178: =IF(G178=I178,1,0) -> 0 | O178: =IF(H178=K178,1,0) -> 0 | P178: In a "wrong" set but tester went below parallel; label may be wrong | Q178: posture_T01_20261013_165543.csv
A179: T01 | B179: Squat | C179: 3 | D179: 8 | E179: 98.8 | F179: 20.3 | G179: Incorrect | H179: =IF(B179="Squat",IF(AND(E179<=Summary!$B$7,OR(F179="",F179<=Summary!$B$8)),"Correct","Incorrect"),IF(AND(E179<=Summary!$B$9,OR(F179="",F179>=Summary!$B$10)),"Correct","Incorrect")) -> Incorrect | I179: Incorrect | J179: No | K179: =IF(J179="Yes",IF(I179="Correct","Incorrect","Correct"),I179) -> Incorrect | L179: =IF(I179="Incorrect",IF(H179="Incorrect","TP","FN"),IF(H179="Incorrect","FP","TN")) -> TP | M179: =IF(H179=I179,1,0) -> 1 | N179: =IF(G179=I179,1,0) -> 1 | O179: =IF(H179=K179,1,0) -> 1 | Q179: posture_T01_20261013_165543.csv
A180: T01 | B180: Squat | C180: 3 | D180: 9 | E180: 89.4 | F180: 22.9 | G180: Incorrect | H180: =IF(B180="Squat",IF(AND(E180<=Summary!$B$7,OR(F180="",F180<=Summary!$B$8)),"Correct","Incorrect"),IF(AND(E180<=Summary!$B$9,OR(F180="",F180>=Summary!$B$10)),"Correct","Incorrect")) -> Incorrect | I180: Incorrect | J180: No | K180: =IF(J180="Yes",IF(I180="Correct","Incorrect","Correct"),I180) -> Incorrect | L180: =IF(I180="Incorrect",IF(H180="Incorrect","TP","FN"),IF(H180="Incorrect","FP","TN")) -> TP | M180: =IF(H180=I180,1,0) -> 1 | N180: =IF(G180=I180,1,0) -> 1 | O180: =IF(H180=K180,1,0) -> 1 | Q180: posture_T01_20261013_165543.csv
A181: T01 | B181: Squat | C181: 3 | D181: 10 | E181: 95.7 | F181: 20.9 | G181: Incorrect | H181: =IF(B181="Squat",IF(AND(E181<=Summary!$B$7,OR(F181="",F181<=Summary!$B$8)),"Correct","Incorrect"),IF(AND(E181<=Summary!$B$9,OR(F181="",F181>=Summary!$B$10)),"Correct","Incorrect")) -> Incorrect | I181: Incorrect | J181: No | K181: =IF(J181="Yes",IF(I181="Correct","Incorrect","Correct"),I181) -> Incorrect | L181: =IF(I181="Incorrect",IF(H181="Incorrect","TP","FN"),IF(H181="Incorrect","FP","TN")) -> TP | M181: =IF(H181=I181,1,0) -> 1 | N181: =IF(G181=I181,1,0) -> 1 | O181: =IF(H181=K181,1,0) -> 1 | Q181: posture_T01_20261013_165543.csv
A182: T02 | B182: Squat | C182: 1 | D182: 1 | E182: 94 | F182: 178.5 | G182: Incorrect | H182: =IF(B182="Squat",IF(AND(E182<=Summary!$B$7,OR(F182="",F182<=Summary!$B$8)),"Correct","Incorrect"),IF(AND(E182<=Summary!$B$9,OR(F182="",F182>=Summary!$B$10)),"Correct","Incorrect")) -> Incorrect | I182: Correct | J182: No | K182: =IF(J182="Yes",IF(I182="Correct","Incorrect","Correct"),I182) -> Correct | L182: =IF(I182="Incorrect",IF(H182="Incorrect","TP","FN"),IF(H182="Incorrect","FP","TN")) -> FP | M182: =IF(H182=I182,1,0) -> 0 | N182: =IF(G182=I182,1,0) -> 0 | O182: =IF(H182=K182,1,0) -> 0 | P182: Pose-tracking glitch: trunk lean / knee angle implausible | Q182: posture_T02_20261013_165037.csv
A183: T02 | B183: Squat | C183: 1 | D183: 2 | E183: 79.9 | F183: 38.8 | G183: Correct | H183: =IF(B183="Squat",IF(AND(E183<=Summary!$B$7,OR(F183="",F183<=Summary!$B$8)),"Correct","Incorrect"),IF(AND(E183<=Summary!$B$9,OR(F183="",F183>=Summary!$B$10)),"Correct","Incorrect")) -> Correct | I183: Correct | J183: No | K183: =IF(J183="Yes",IF(I183="Correct","Incorrect","Correct"),I183) -> Correct | L183: =IF(I183="Incorrect",IF(H183="Incorrect","TP","FN"),IF(H183="Incorrect","FP","TN")) -> TN | M183: =IF(H183=I183,1,0) -> 1 | N183: =IF(G183=I183,1,0) -> 1 | O183: =IF(H183=K183,1,0) -> 1 | Q183: posture_T02_20261013_165037.csv
A184: T02 | B184: Squat | C184: 1 | D184: 3 | E184: 70.2 | F184: 32.6 | G184: Correct | H184: =IF(B184="Squat",IF(AND(E184<=Summary!$B$7,OR(F184="",F184<=Summary!$B$8)),"Correct","Incorrect"),IF(AND(E184<=Summary!$B$9,OR(F184="",F184>=Summary!$B$10)),"Correct","Incorrect")) -> Correct | I184: Correct | J184: No | K184: =IF(J184="Yes",IF(I184="Correct","Incorrect","Correct"),I184) -> Correct | L184: =IF(I184="Incorrect",IF(H184="Incorrect","TP","FN"),IF(H184="Incorrect","FP","TN")) -> TN | M184: =IF(H184=I184,1,0) -> 1 | N184: =IF(G184=I184,1,0) -> 1 | O184: =IF(H184=K184,1,0) -> 1 | Q184: posture_T02_20261013_165037.csv
A185: T02 | B185: Squat | C185: 1 | D185: 4 | E185: 66.2 | F185: 40.2 | G185: Correct | H185: =IF(B185="Squat",IF(AND(E185<=Summary!$B$7,OR(F185="",F185<=Summary!$B$8)),"Correct","Incorrect"),IF(AND(E185<=Summary!$B$9,OR(F185="",F185>=Summary!$B$10)),"Correct","Incorrect")) -> Correct | I185: Correct | J185: No | K185: =IF(J185="Yes",IF(I185="Correct","Incorrect","Correct"),I185) -> Correct | L185: =IF(I185="Incorrect",IF(H185="Incorrect","TP","FN"),IF(H185="Incorrect","FP","TN")) -> TN | M185: =IF(H185=I185,1,0) -> 1 | N185: =IF(G185=I185,1,0) -> 1 | O185: =IF(H185=K185,1,0) -> 1 | Q185: posture_T02_20261013_165037.csv
A186: T02 | B186: Squat | C186: 1 | D186: 5 | E186: 79.2 | F186: 35.6 | G186: Correct | H186: =IF(B186="Squat",IF(AND(E186<=Summary!$B$7,OR(F186="",F186<=Summary!$B$8)),"Correct","Incorrect"),IF(AND(E186<=Summary!$B$9,OR(F186="",F186>=Summary!$B$10)),"Correct","Incorrect")) -> Correct | I186: Correct | J186: No | K186: =IF(J186="Yes",IF(I186="Correct","Incorrect","Correct"),I186) -> Correct | L186: =IF(I186="Incorrect",IF(H186="Incorrect","TP","FN"),IF(H186="Incorrect","FP","TN")) -> TN | M186: =IF(H186=I186,1,0) -> 1 | N186: =IF(G186=I186,1,0) -> 1 | O186: =IF(H186=K186,1,0) -> 1 | Q186: posture_T02_20261013_165037.csv
A187: T02 | B187: Squat | C187: 1 | D187: 6 | E187: 77.2 | F187: 35.8 | G187: Correct | H187: =IF(B187="Squat",IF(AND(E187<=Summary!$B$7,OR(F187="",F187<=Summary!$B$8)),"Correct","Incorrect"),IF(AND(E187<=Summary!$B$9,OR(F187="",F187>=Summary!$B$10)),"Correct","Incorrect")) -> Correct | I187: Correct | J187: No | K187: =IF(J187="Yes",IF(I187="Correct","Incorrect","Correct"),I187) -> Correct | L187: =IF(I187="Incorrect",IF(H187="Incorrect","TP","FN"),IF(H187="Incorrect","FP","TN")) -> TN | M187: =IF(H187=I187,1,0) -> 1 | N187: =IF(G187=I187,1,0) -> 1 | O187: =IF(H187=K187,1,0) -> 1 | Q187: posture_T02_20261013_165037.csv
A188: T02 | B188: Squat | C188: 1 | D188: 7 | E188: 74.4 | F188: 35.3 | G188: Correct | H188: =IF(B188="Squat",IF(AND(E188<=Summary!$B$7,OR(F188="",F188<=Summary!$B$8)),"Correct","Incorrect"),IF(AND(E188<=Summary!$B$9,OR(F188="",F188>=Summary!$B$10)),"Correct","Incorrect")) -> Correct | I188: Correct | J188: No | K188: =IF(J188="Yes",IF(I188="Correct","Incorrect","Correct"),I188) -> Correct | L188: =IF(I188="Incorrect",IF(H188="Incorrect","TP","FN"),IF(H188="Incorrect","FP","TN")) -> TN | M188: =IF(H188=I188,1,0) -> 1 | N188: =IF(G188=I188,1,0) -> 1 | O188: =IF(H188=K188,1,0) -> 1 | Q188: posture_T02_20261013_165037.csv
A189: T02 | B189: Squat | C189: 1 | D189: 8 | E189: 77.2 | F189: 37.1 | G189: Correct | H189: =IF(B189="Squat",IF(AND(E189<=Summary!$B$7,OR(F189="",F189<=Summary!$B$8)),"Correct","Incorrect"),IF(AND(E189<=Summary!$B$9,OR(F189="",F189>=Summary!$B$10)),"Correct","Incorrect")) -> Correct | I189: Correct | J189: No | K189: =IF(J189="Yes",IF(I189="Correct","Incorrect","Correct"),I189) -> Correct | L189: =IF(I189="Incorrect",IF(H189="Incorrect","TP","FN"),IF(H189="Incorrect","FP","TN")) -> TN | M189: =IF(H189=I189,1,0) -> 1 | N189: =IF(G189=I189,1,0) -> 1 | O189: =IF(H189=K189,1,0) -> 1 | Q189: posture_T02_20261013_165037.csv
...

Sheet Issues & Next Steps
A1: Issues found in the data, and what to do
A3: Priority | B3: Issue | C3: Detail | D3: Action
A4: HIGH | B4: 4 squat verdicts edited (T02, set 2) | C4: Reps 1, 2, 4, 7 have knee angles 81–84° (over the 80° limit) but are stored as "TRUE". The code cannot output TRUE for those, and the file shows signs of being re-saved in Excel (TRUE/FALSE in capitals, "94" instead of "94.0"). | D4: Confirm what happened. Main result uses the code-rule verdict. Never open the CSVs in Excel and save; open a copy.
A5: HIGH | B5: Observer flips all moved towards the app | C5: 5 net flips (T01 squat s2 r3; T03 squat s1 r1–3; T03 squat s2 r9). Each one made the label agree with the app. Fine if based on what you SAW the tester do; not fine if based on the app's verdict. | D5: Confirm each flip was based on observation. If unsure, report the "ignoring flips" figure too (sensitivity table).
A6: MEDIUM | B6: Unbalanced testers | C6: T01 push-up: all 30 reps wrong. T03 push-up: all 30 correct. T04 squat: all 30 wrong. Classes are balanced overall (push-up 70/80, squat 77/73), but per-tester accuracy is not comparable. | D6: State it in the methodology. No re-test needed.
A7: MEDIUM | B7: Fault types not recorded | C7: Every "wrong" set was entered as plain "i" without a fault name, so you can't report accuracy per fault (shallow vs sag vs lean). | D7: Write down from memory which fault each wrong set was, if you can; otherwise state it as a limitation.
A8: MEDIUM | B8: Possible mislabels in "wrong" squat sets | C8: T01 s3 r7 (70°), T02 s3 r1, r2, r6 (64°, 64°, 41°): these went below parallel in a "shallow" set. The app said correct, so they count as misses, but the tester probably did a good rep. | D8: Keep as-is (no video to prove it). Mention as a source of error.
A9: LOW | B9: 2 pose-tracking glitches | C9: T02 squat s1 r1 (trunk 178.5°) and T03 squat s1 r2 (knee 15.8°, trunk 172.4°) are physically impossible readings: MediaPipe lost the body for a frame. | D9: Keep in the data; mention as a real-world failure mode.
A10: LOW | B10: Exaggerated faults | C10: Wrong reps were clearly wrong (squats stopped at 95–110°, push-up body line 55–145°), so classes are well separated. Push-up 100% reflects this. | D10: State it: borderline/subtle faults were not tested, so real-world accuracy may be lower.
A11: NEXT | B11: Deadlift | C11: Still no data. The deadlift analyser has no fault check (no spine landmarks). | D11: Report as a limitation, or run a correct-only round to show rep counting works.
A12: NEXT | B12: Write-up | C12: Results are ready for the Evaluation chapter. | D12: Use the Summary tables; cite the pilot round as the first iteration.
A14: Legend
A15: Blue text | B15: Typed-in values (from the CSVs or settings)
A16: Yellow fill | B16: Editable: ground-truth labels and the target
A17: Black text | B17: Formulas: do not overwrite
A18: Orange cell | B18: Logged verdict differs from the code rule
